2019-01-17 20:02:32,171 (4940/MainThread) litecli.main ERROR - sql: '.help', error: OperationalError('near ".": syntax error')
2019-01-17 20:02:32,172 (4940/MainThread) litecli.main ERROR - traceback: 'Traceback (most recent call last):\n  File "/home/andmalc/Envs/litecli/lib/python3.7/site-packages/litecli/sqlexecute.py", line 116, in run\n    for result in special.execute(cur, sql):\n  File "/home/andmalc/Envs/litecli/lib/python3.7/site-packages/litecli/packages/special/main.py", line 104, in execute\n    raise CommandNotFound\nlitecli.packages.special.main.CommandNotFound\n\nDuring handling of the above exception, another exception occurred:\n\nTraceback (most recent call last):\n  File "/home/andmalc/Envs/litecli/lib/python3.7/site-packages/litecli/main.py", line 440, in one_iteration\n    for title, cur, headers, status in res:\n  File "/home/andmalc/Envs/litecli/lib/python3.7/site-packages/litecli/sqlexecute.py", line 120, in run\n    cur.execute(sql)\nsqlite3.OperationalError: near ".": syntax error\n'
2019-01-17 20:05:57,593 (4940/MainThread) litecli.main ERROR - sql: 'create ta', error: OperationalError('near "ta": syntax error')
2019-01-17 20:05:57,594 (4940/MainThread) litecli.main ERROR - traceback: 'Traceback (most recent call last):\n  File "/home/andmalc/Envs/litecli/lib/python3.7/site-packages/litecli/sqlexecute.py", line 116, in run\n    for result in special.execute(cur, sql):\n  File "/home/andmalc/Envs/litecli/lib/python3.7/site-packages/litecli/packages/special/main.py", line 104, in execute\n    raise CommandNotFound\nlitecli.packages.special.main.CommandNotFound\n\nDuring handling of the above exception, another exception occurred:\n\nTraceback (most recent call last):\n  File "/home/andmalc/Envs/litecli/lib/python3.7/site-packages/litecli/main.py", line 440, in one_iteration\n    for title, cur, headers, status in res:\n  File "/home/andmalc/Envs/litecli/lib/python3.7/site-packages/litecli/sqlexecute.py", line 120, in run\n    cur.execute(sql)\nsqlite3.OperationalError: near "ta": syntax error\n'
2019-01-17 20:06:41,052 (4940/MainThread) litecli.main ERROR - sql: 'create table testtable ( firstname text, lastname te', error: OperationalError('incomplete input')
2019-01-17 20:06:41,053 (4940/MainThread) litecli.main ERROR - traceback: 'Traceback (most recent call last):\n  File "/home/andmalc/Envs/litecli/lib/python3.7/site-packages/litecli/sqlexecute.py", line 116, in run\n    for result in special.execute(cur, sql):\n  File "/home/andmalc/Envs/litecli/lib/python3.7/site-packages/litecli/packages/special/main.py", line 104, in execute\n    raise CommandNotFound\nlitecli.packages.special.main.CommandNotFound\n\nDuring handling of the above exception, another exception occurred:\n\nTraceback (most recent call last):\n  File "/home/andmalc/Envs/litecli/lib/python3.7/site-packages/litecli/main.py", line 440, in one_iteration\n    for title, cur, headers, status in res:\n  File "/home/andmalc/Envs/litecli/lib/python3.7/site-packages/litecli/sqlexecute.py", line 120, in run\n    cur.execute(sql)\nsqlite3.OperationalError: incomplete input\n'
2019-01-29 15:08:07,097 (24147/MainThread) litecli.main ERROR - sql: 'ls', error: OperationalError('near "ls": syntax error')
2019-01-29 15:08:07,121 (24147/MainThread) litecli.main ERROR - traceback: 'Traceback (most recent call last):\n  File "/home/andmalc/.local/share/virtualenvs/data-P6VU3CWE/lib/python3.7/site-packages/litecli/sqlexecute.py", line 116, in run\n    for result in special.execute(cur, sql):\n  File "/home/andmalc/.local/share/virtualenvs/data-P6VU3CWE/lib/python3.7/site-packages/litecli/packages/special/main.py", line 104, in execute\n    raise CommandNotFound\nlitecli.packages.special.main.CommandNotFound\n\nDuring handling of the above exception, another exception occurred:\n\nTraceback (most recent call last):\n  File "/home/andmalc/.local/share/virtualenvs/data-P6VU3CWE/lib/python3.7/site-packages/litecli/main.py", line 440, in one_iteration\n    for title, cur, headers, status in res:\n  File "/home/andmalc/.local/share/virtualenvs/data-P6VU3CWE/lib/python3.7/site-packages/litecli/sqlexecute.py", line 120, in run\n    cur.execute(sql)\nsqlite3.OperationalError: near "ls": syntax error\n'
2019-01-29 16:09:23,997 (24147/MainThread) litecli.main ERROR - sql: '.quit', error: OperationalError('near ".": syntax error')
2019-01-29 16:09:23,997 (24147/MainThread) litecli.main ERROR - traceback: 'Traceback (most recent call last):\n  File "/home/andmalc/.local/share/virtualenvs/data-P6VU3CWE/lib/python3.7/site-packages/litecli/sqlexecute.py", line 116, in run\n    for result in special.execute(cur, sql):\n  File "/home/andmalc/.local/share/virtualenvs/data-P6VU3CWE/lib/python3.7/site-packages/litecli/packages/special/main.py", line 104, in execute\n    raise CommandNotFound\nlitecli.packages.special.main.CommandNotFound\n\nDuring handling of the above exception, another exception occurred:\n\nTraceback (most recent call last):\n  File "/home/andmalc/.local/share/virtualenvs/data-P6VU3CWE/lib/python3.7/site-packages/litecli/main.py", line 440, in one_iteration\n    for title, cur, headers, status in res:\n  File "/home/andmalc/.local/share/virtualenvs/data-P6VU3CWE/lib/python3.7/site-packages/litecli/sqlexecute.py", line 120, in run\n    cur.execute(sql)\nsqlite3.OperationalError: near ".": syntax error\n'
2019-01-29 16:09:29,947 (24147/MainThread) litecli.main ERROR - sql: '.e', error: OperationalError('near ".": syntax error')
2019-01-29 16:09:29,947 (24147/MainThread) litecli.main ERROR - traceback: 'Traceback (most recent call last):\n  File "/home/andmalc/.local/share/virtualenvs/data-P6VU3CWE/lib/python3.7/site-packages/litecli/sqlexecute.py", line 116, in run\n    for result in special.execute(cur, sql):\n  File "/home/andmalc/.local/share/virtualenvs/data-P6VU3CWE/lib/python3.7/site-packages/litecli/packages/special/main.py", line 104, in execute\n    raise CommandNotFound\nlitecli.packages.special.main.CommandNotFound\n\nDuring handling of the above exception, another exception occurred:\n\nTraceback (most recent call last):\n  File "/home/andmalc/.local/share/virtualenvs/data-P6VU3CWE/lib/python3.7/site-packages/litecli/main.py", line 440, in one_iteration\n    for title, cur, headers, status in res:\n  File "/home/andmalc/.local/share/virtualenvs/data-P6VU3CWE/lib/python3.7/site-packages/litecli/sqlexecute.py", line 120, in run\n    cur.execute(sql)\nsqlite3.OperationalError: near ".": syntax error\n'
2019-01-29 16:24:02,791 (15264/MainThread) litecli.main ERROR - sql: '.version', error: OperationalError('near ".": syntax error')
2019-01-29 16:24:02,799 (15264/MainThread) litecli.main ERROR - traceback: 'Traceback (most recent call last):\n  File "/home/andmalc/.local/share/virtualenvs/data-P6VU3CWE/lib/python3.7/site-packages/litecli/sqlexecute.py", line 116, in run\n    for result in special.execute(cur, sql):\n  File "/home/andmalc/.local/share/virtualenvs/data-P6VU3CWE/lib/python3.7/site-packages/litecli/packages/special/main.py", line 104, in execute\n    raise CommandNotFound\nlitecli.packages.special.main.CommandNotFound\n\nDuring handling of the above exception, another exception occurred:\n\nTraceback (most recent call last):\n  File "/home/andmalc/.local/share/virtualenvs/data-P6VU3CWE/lib/python3.7/site-packages/litecli/main.py", line 440, in one_iteration\n    for title, cur, headers, status in res:\n  File "/home/andmalc/.local/share/virtualenvs/data-P6VU3CWE/lib/python3.7/site-packages/litecli/sqlexecute.py", line 120, in run\n    cur.execute(sql)\nsqlite3.OperationalError: near ".": syntax error\n'
2019-01-30 19:51:51,092 (11301/MainThread) litecli.main ERROR - sql: '.output', error: OperationalError('near ".": syntax error')
2019-01-30 19:51:51,116 (11301/MainThread) litecli.main ERROR - traceback: 'Traceback (most recent call last):\n  File "/home/andmalc/.local/share/virtualenvs/data-P6VU3CWE/lib/python3.7/site-packages/litecli/sqlexecute.py", line 116, in run\n    for result in special.execute(cur, sql):\n  File "/home/andmalc/.local/share/virtualenvs/data-P6VU3CWE/lib/python3.7/site-packages/litecli/packages/special/main.py", line 104, in execute\n    raise CommandNotFound\nlitecli.packages.special.main.CommandNotFound\n\nDuring handling of the above exception, another exception occurred:\n\nTraceback (most recent call last):\n  File "/home/andmalc/.local/share/virtualenvs/data-P6VU3CWE/lib/python3.7/site-packages/litecli/main.py", line 440, in one_iteration\n    for title, cur, headers, status in res:\n  File "/home/andmalc/.local/share/virtualenvs/data-P6VU3CWE/lib/python3.7/site-packages/litecli/sqlexecute.py", line 120, in run\n    cur.execute(sql)\nsqlite3.OperationalError: near ".": syntax error\n'
2019-01-30 19:52:53,357 (11301/MainThread) litecli.main ERROR - sql: '\\t grid', error: OperationalError('unrecognized token: "\\"')
2019-01-30 19:52:53,357 (11301/MainThread) litecli.main ERROR - traceback: 'Traceback (most recent call last):\n  File "/home/andmalc/.local/share/virtualenvs/data-P6VU3CWE/lib/python3.7/site-packages/litecli/sqlexecute.py", line 116, in run\n    for result in special.execute(cur, sql):\n  File "/home/andmalc/.local/share/virtualenvs/data-P6VU3CWE/lib/python3.7/site-packages/litecli/packages/special/main.py", line 104, in execute\n    raise CommandNotFound\nlitecli.packages.special.main.CommandNotFound\n\nDuring handling of the above exception, another exception occurred:\n\nTraceback (most recent call last):\n  File "/home/andmalc/.local/share/virtualenvs/data-P6VU3CWE/lib/python3.7/site-packages/litecli/main.py", line 440, in one_iteration\n    for title, cur, headers, status in res:\n  File "/home/andmalc/.local/share/virtualenvs/data-P6VU3CWE/lib/python3.7/site-packages/litecli/sqlexecute.py", line 120, in run\n    cur.execute(sql)\nsqlite3.OperationalError: unrecognized token: "\\"\n'
2019-01-30 19:57:56,787 (11301/MainThread) litecli.main ERROR - sql: "select writefile('out') from cities;", error: OperationalError('no such function: writefile')
2019-01-30 19:57:56,788 (11301/MainThread) litecli.main ERROR - traceback: 'Traceback (most recent call last):\n  File "/home/andmalc/.local/share/virtualenvs/data-P6VU3CWE/lib/python3.7/site-packages/litecli/sqlexecute.py", line 116, in run\n    for result in special.execute(cur, sql):\n  File "/home/andmalc/.local/share/virtualenvs/data-P6VU3CWE/lib/python3.7/site-packages/litecli/packages/special/main.py", line 104, in execute\n    raise CommandNotFound\nlitecli.packages.special.main.CommandNotFound\n\nDuring handling of the above exception, another exception occurred:\n\nTraceback (most recent call last):\n  File "/home/andmalc/.local/share/virtualenvs/data-P6VU3CWE/lib/python3.7/site-packages/litecli/main.py", line 440, in one_iteration\n    for title, cur, headers, status in res:\n  File "/home/andmalc/.local/share/virtualenvs/data-P6VU3CWE/lib/python3.7/site-packages/litecli/sqlexecute.py", line 120, in run\n    cur.execute(sql)\nsqlite3.OperationalError: no such function: writefile\n'
